[2024-08-01T17:46:16.107+0000] {logging_mixin.py:149} WARNING - /home/***/.local/lib/python3.7/site-packages/***/utils/sqlalchemy.py:124 DeprecationWarning: The sql_alchemy_conn option in [core] has been moved to the sql_alchemy_conn option in [database] - the old setting has been used, but please update your config.
[2024-08-01T17:46:16.126+0000] {taskinstance.py:1103} INFO - Dependencies all met for dep_context=non-requeueable deps ti=<TaskInstance: nyc_taxi_etl_2023.process_month_01 scheduled__2023-01-01T00:00:00+00:00 [queued]>
[2024-08-01T17:46:16.138+0000] {taskinstance.py:1103} INFO - Dependencies all met for dep_context=requeueable deps ti=<TaskInstance: nyc_taxi_etl_2023.process_month_01 scheduled__2023-01-01T00:00:00+00:00 [queued]>
[2024-08-01T17:46:16.139+0000] {taskinstance.py:1308} INFO - Starting attempt 1 of 2
[2024-08-01T17:46:16.154+0000] {taskinstance.py:1327} INFO - Executing <Task(PythonOperator): process_month_01> on 2023-01-01 00:00:00+00:00
[2024-08-01T17:46:16.186+0000] {standard_task_runner.py:84} INFO - Running: ['***', 'tasks', 'run', 'nyc_taxi_etl_2023', 'process_month_01', 'scheduled__2023-01-01T00:00:00+00:00', '--job-id', '2', '--raw', '--subdir', 'DAGS_FOLDER/nyc_taxi_etl.py', '--cfg-path', '/tmp/tmpkik87cl6']
[2024-08-01T17:46:16.189+0000] {standard_task_runner.py:85} INFO - Job 2: Subtask process_month_01
[2024-08-01T17:46:16.185+0000] {standard_task_runner.py:57} INFO - Started process 78 to run task
[2024-08-01T17:46:16.223+0000] {logging_mixin.py:149} WARNING - /home/***/.local/lib/python3.7/site-packages/***/settings.py:195 DeprecationWarning: The sql_alchemy_conn option in [core] has been moved to the sql_alchemy_conn option in [database] - the old setting has been used, but please update your config.
[2024-08-01T17:46:16.415+0000] {task_command.py:410} INFO - Running <TaskInstance: nyc_taxi_etl_2023.process_month_01 scheduled__2023-01-01T00:00:00+00:00 [running]> on host 3a96f4659d34
[2024-08-01T17:46:17.289+0000] {logging_mixin.py:149} WARNING - /home/***/.local/lib/python3.7/site-packages/***/utils/sqlalchemy.py:124 DeprecationWarning: The sql_alchemy_conn option in [core] has been moved to the sql_alchemy_conn option in [database] - the old setting has been used, but please update your config.
[2024-08-01T17:46:17.402+0000] {taskinstance.py:1547} INFO - Exporting env vars: AIRFLOW_CTX_DAG_OWNER='***' AIRFLOW_CTX_DAG_ID='nyc_taxi_etl_2023' AIRFLOW_CTX_TASK_ID='process_month_01' AIRFLOW_CTX_EXECUTION_DATE='2023-01-01T00:00:00+00:00' AIRFLOW_CTX_TRY_NUMBER='1' AIRFLOW_CTX_DAG_RUN_ID='scheduled__2023-01-01T00:00:00+00:00'
[2024-08-01T17:46:31.792+0000] {taskinstance.py:1824} ERROR - Task failed with exception
Traceback (most recent call last):
  File "/home/airflow/.local/lib/python3.7/site-packages/airflow/operators/python.py", line 181, in execute
    return_value = self.execute_callable()
  File "/home/airflow/.local/lib/python3.7/site-packages/airflow/operators/python.py", line 198, in execute_callable
    return self.python_callable(*self.op_args, **self.op_kwargs)
  File "/opt/airflow/dags/nyc_taxi_etl.py", line 27, in process_month
    upload_to_gcs(get_credentials(), os.environ.get('GCP_BUCKET_ID'), f"data/{file_name}", f"raw/{file_name}")
  File "/opt/airflow/scripts/ingest_data.py", line 28, in upload_to_gcs
    blob.upload_from_filename(source_file_name)
  File "/home/airflow/.local/lib/python3.7/site-packages/google/cloud/storage/blob.py", line 2697, in upload_from_filename
    retry=retry,
  File "/home/airflow/.local/lib/python3.7/site-packages/google/cloud/storage/blob.py", line 2553, in upload_from_file
    retry=retry,
  File "/home/airflow/.local/lib/python3.7/site-packages/google/cloud/storage/blob.py", line 2384, in _do_upload
    retry=retry,
  File "/home/airflow/.local/lib/python3.7/site-packages/google/cloud/storage/blob.py", line 2211, in _do_resumable_upload
    retry=retry,
  File "/home/airflow/.local/lib/python3.7/site-packages/google/cloud/storage/blob.py", line 2086, in _initiate_resumable_upload
    timeout=timeout,
  File "/home/airflow/.local/lib/python3.7/site-packages/google/resumable_media/requests/upload.py", line 421, in initiate
    retriable_request, self._get_status_code, self._retry_strategy
  File "/home/airflow/.local/lib/python3.7/site-packages/google/resumable_media/requests/_request_helpers.py", line 155, in wait_and_retry
    response = func()
  File "/home/airflow/.local/lib/python3.7/site-packages/google/resumable_media/requests/upload.py", line 413, in retriable_request
    method, url, data=payload, headers=headers, timeout=timeout
  File "/home/airflow/.local/lib/python3.7/site-packages/google/auth/transport/requests.py", line 545, in request
    self.credentials.before_request(auth_request, method, url, request_headers)
  File "/home/airflow/.local/lib/python3.7/site-packages/google/auth/credentials.py", line 135, in before_request
    self.refresh(request)
  File "/home/airflow/.local/lib/python3.7/site-packages/google/oauth2/service_account.py", line 426, in refresh
    request, self._token_uri, assertion
  File "/home/airflow/.local/lib/python3.7/site-packages/google/oauth2/_client.py", line 304, in jwt_grant
    request, token_uri, body, can_retry=can_retry
  File "/home/airflow/.local/lib/python3.7/site-packages/google/oauth2/_client.py", line 274, in _token_endpoint_request
    _handle_error_response(response_data, retryable_error)
  File "/home/airflow/.local/lib/python3.7/site-packages/google/oauth2/_client.py", line 74, in _handle_error_response
    error_details, response_data, retryable=retryable_error
google.auth.exceptions.RefreshError: ('invalid_grant: Invalid JWT Signature.', {'error': 'invalid_grant', 'error_description': 'Invalid JWT Signature.'})
[2024-08-01T17:46:31.837+0000] {taskinstance.py:1350} INFO - Marking task as UP_FOR_RETRY. dag_id=nyc_taxi_etl_2023, task_id=process_month_01, execution_date=20230101T000000, start_date=20240801T174616, end_date=20240801T174631
[2024-08-01T17:46:31.877+0000] {standard_task_runner.py:109} ERROR - Failed to execute job 2 for task process_month_01 (('invalid_grant: Invalid JWT Signature.', {'error': 'invalid_grant', 'error_description': 'Invalid JWT Signature.'}); 78)
[2024-08-01T17:46:31.946+0000] {local_task_job_runner.py:225} INFO - Task exited with return code 1
[2024-08-01T17:46:32.345+0000] {taskinstance.py:2651} INFO - 0 downstream tasks scheduled from follow-on schedule check
[2024-08-01T17:55:43.030+0000] {logging_mixin.py:149} WARNING - /home/***/.local/lib/python3.7/site-packages/***/utils/sqlalchemy.py:124 DeprecationWarning: The sql_alchemy_conn option in [core] has been moved to the sql_alchemy_conn option in [database] - the old setting has been used, but please update your config.
[2024-08-01T17:55:43.045+0000] {taskinstance.py:1103} INFO - Dependencies all met for dep_context=non-requeueable deps ti=<TaskInstance: nyc_taxi_etl_2023.process_month_01 scheduled__2023-01-01T00:00:00+00:00 [queued]>
[2024-08-01T17:55:43.053+0000] {taskinstance.py:1103} INFO - Dependencies all met for dep_context=requeueable deps ti=<TaskInstance: nyc_taxi_etl_2023.process_month_01 scheduled__2023-01-01T00:00:00+00:00 [queued]>
[2024-08-01T17:55:43.053+0000] {taskinstance.py:1308} INFO - Starting attempt 1 of 2
[2024-08-01T17:55:43.066+0000] {taskinstance.py:1327} INFO - Executing <Task(PythonOperator): process_month_01> on 2023-01-01 00:00:00+00:00
[2024-08-01T17:55:43.075+0000] {standard_task_runner.py:57} INFO - Started process 91 to run task
[2024-08-01T17:55:43.084+0000] {standard_task_runner.py:84} INFO - Running: ['***', 'tasks', 'run', 'nyc_taxi_etl_2023', 'process_month_01', 'scheduled__2023-01-01T00:00:00+00:00', '--job-id', '14', '--raw', '--subdir', 'DAGS_FOLDER/nyc_taxi_etl.py', '--cfg-path', '/tmp/tmpd6xcsmcs']
[2024-08-01T17:55:43.090+0000] {standard_task_runner.py:85} INFO - Job 14: Subtask process_month_01
[2024-08-01T17:55:43.117+0000] {logging_mixin.py:149} WARNING - /home/***/.local/lib/python3.7/site-packages/***/settings.py:195 DeprecationWarning: The sql_alchemy_conn option in [core] has been moved to the sql_alchemy_conn option in [database] - the old setting has been used, but please update your config.
[2024-08-01T17:55:43.195+0000] {task_command.py:410} INFO - Running <TaskInstance: nyc_taxi_etl_2023.process_month_01 scheduled__2023-01-01T00:00:00+00:00 [running]> on host 6d66194ad4f7
[2024-08-01T17:55:43.619+0000] {logging_mixin.py:149} WARNING - /home/***/.local/lib/python3.7/site-packages/***/utils/sqlalchemy.py:124 DeprecationWarning: The sql_alchemy_conn option in [core] has been moved to the sql_alchemy_conn option in [database] - the old setting has been used, but please update your config.
[2024-08-01T17:55:43.707+0000] {taskinstance.py:1547} INFO - Exporting env vars: AIRFLOW_CTX_DAG_OWNER='***' AIRFLOW_CTX_DAG_ID='nyc_taxi_etl_2023' AIRFLOW_CTX_TASK_ID='process_month_01' AIRFLOW_CTX_EXECUTION_DATE='2023-01-01T00:00:00+00:00' AIRFLOW_CTX_TRY_NUMBER='1' AIRFLOW_CTX_DAG_RUN_ID='scheduled__2023-01-01T00:00:00+00:00'
[2024-08-01T17:57:29.249+0000] {logging_mixin.py:149} INFO - Loaded dim_vendor for 2023-01 to BigQuery
[2024-08-01T17:57:35.230+0000] {logging_mixin.py:149} INFO - Loaded dim_rate_code for 2023-01 to BigQuery
[2024-08-01T17:57:39.940+0000] {logging_mixin.py:149} INFO - Loaded dim_payment_type for 2023-01 to BigQuery
[2024-08-01T17:57:46.196+0000] {logging_mixin.py:149} INFO - Loaded dim_location for 2023-01 to BigQuery
[2024-08-01T17:59:15.072+0000] {logging_mixin.py:149} INFO - Loaded fact_trip for 2023-01 to BigQuery
[2024-08-01T17:59:15.079+0000] {python.py:183} INFO - Done. Returned value was: None
[2024-08-01T17:59:15.162+0000] {taskinstance.py:1350} INFO - Marking task as SUCCESS. dag_id=nyc_taxi_etl_2023, task_id=process_month_01, execution_date=20230101T000000, start_date=20240801T175543, end_date=20240801T175915
[2024-08-01T17:59:15.381+0000] {local_task_job_runner.py:225} INFO - Task exited with return code 0
[2024-08-01T17:59:16.025+0000] {taskinstance.py:2651} INFO - 1 downstream tasks scheduled from follow-on schedule check
