[2024-08-01T18:29:48.220+0000] {logging_mixin.py:149} WARNING - /home/***/.local/lib/python3.7/site-packages/***/utils/sqlalchemy.py:124 DeprecationWarning: The sql_alchemy_conn option in [core] has been moved to the sql_alchemy_conn option in [database] - the old setting has been used, but please update your config.
[2024-08-01T18:29:48.231+0000] {taskinstance.py:1103} INFO - Dependencies all met for dep_context=non-requeueable deps ti=<TaskInstance: nyc_taxi_etl_2023.process_month_02 scheduled__2023-01-04T00:00:00+00:00 [queued]>
[2024-08-01T18:29:48.239+0000] {taskinstance.py:1103} INFO - Dependencies all met for dep_context=requeueable deps ti=<TaskInstance: nyc_taxi_etl_2023.process_month_02 scheduled__2023-01-04T00:00:00+00:00 [queued]>
[2024-08-01T18:29:48.239+0000] {taskinstance.py:1308} INFO - Starting attempt 2 of 2
[2024-08-01T18:29:48.252+0000] {taskinstance.py:1327} INFO - Executing <Task(PythonOperator): process_month_02> on 2023-01-04 00:00:00+00:00
[2024-08-01T18:29:48.261+0000] {standard_task_runner.py:57} INFO - Started process 1497 to run task
[2024-08-01T18:29:48.278+0000] {standard_task_runner.py:84} INFO - Running: ['***', 'tasks', 'run', 'nyc_taxi_etl_2023', 'process_month_02', 'scheduled__2023-01-04T00:00:00+00:00', '--job-id', '29', '--raw', '--subdir', 'DAGS_FOLDER/nyc_taxi_etl.py', '--cfg-path', '/tmp/tmprg6hls11']
[2024-08-01T18:29:48.281+0000] {standard_task_runner.py:85} INFO - Job 29: Subtask process_month_02
[2024-08-01T18:29:48.302+0000] {logging_mixin.py:149} WARNING - /home/***/.local/lib/python3.7/site-packages/***/settings.py:195 DeprecationWarning: The sql_alchemy_conn option in [core] has been moved to the sql_alchemy_conn option in [database] - the old setting has been used, but please update your config.
[2024-08-01T18:29:48.344+0000] {task_command.py:410} INFO - Running <TaskInstance: nyc_taxi_etl_2023.process_month_02 scheduled__2023-01-04T00:00:00+00:00 [running]> on host 6d66194ad4f7
[2024-08-01T18:29:48.364+0000] {logging_mixin.py:149} WARNING - /home/***/.local/lib/python3.7/site-packages/***/utils/sqlalchemy.py:124 DeprecationWarning: The sql_alchemy_conn option in [core] has been moved to the sql_alchemy_conn option in [database] - the old setting has been used, but please update your config.
[2024-08-01T18:29:49.085+0000] {taskinstance.py:1547} INFO - Exporting env vars: AIRFLOW_CTX_DAG_OWNER='***' AIRFLOW_CTX_DAG_ID='nyc_taxi_etl_2023' AIRFLOW_CTX_TASK_ID='process_month_02' AIRFLOW_CTX_EXECUTION_DATE='2023-01-04T00:00:00+00:00' AIRFLOW_CTX_TRY_NUMBER='2' AIRFLOW_CTX_DAG_RUN_ID='scheduled__2023-01-04T00:00:00+00:00'
[2024-08-01T18:30:38.495+0000] {transform_data.py:18} INFO - Processing data for 2023-02
[2024-08-01T18:30:38.499+0000] {transform_data.py:19} INFO - Columns in the dataset: ['VendorID', 'tpep_pickup_datetime', 'tpep_dropoff_datetime', 'passenger_count', 'trip_distance', 'RatecodeID', 'store_and_fwd_flag', 'PULocationID', 'DOLocationID', 'payment_type', 'fare_amount', 'extra', 'mta_tax', 'tip_amount', 'tolls_amount', 'improvement_surcharge', 'total_amount', 'congestion_surcharge', 'Airport_fee']
[2024-08-01T18:30:45.670+0000] {transform_data.py:77} ERROR - Error processing data for 2023-02: "['airport_fee'] not in index"
[2024-08-01T18:30:45.774+0000] {taskinstance.py:1824} ERROR - Task failed with exception
Traceback (most recent call last):
  File "/home/airflow/.local/lib/python3.7/site-packages/airflow/operators/python.py", line 181, in execute
    return_value = self.execute_callable()
  File "/home/airflow/.local/lib/python3.7/site-packages/airflow/operators/python.py", line 198, in execute_callable
    return self.python_callable(*self.op_args, **self.op_kwargs)
  File "/opt/airflow/dags/nyc_taxi_etl.py", line 28, in process_month
    clean_and_transform_data(year, month)
  File "/opt/airflow/scripts/transform_data.py", line 74, in clean_and_transform_data
    clean_and_transform_data(year, month)
  File "/opt/airflow/scripts/transform_data.py", line 123, in create_fact_table
  File "/home/airflow/.local/lib/python3.7/site-packages/pandas/core/frame.py", line 3464, in __getitem__
    indexer = self.loc._get_listlike_indexer(key, axis=1)[1]
  File "/home/airflow/.local/lib/python3.7/site-packages/pandas/core/indexing.py", line 1314, in _get_listlike_indexer
    self._validate_read_indexer(keyarr, indexer, axis)
  File "/home/airflow/.local/lib/python3.7/site-packages/pandas/core/indexing.py", line 1377, in _validate_read_indexer
    raise KeyError(f"{not_found} not in index")
KeyError: "['airport_fee'] not in index"
[2024-08-01T18:30:46.309+0000] {taskinstance.py:1350} INFO - Marking task as FAILED. dag_id=nyc_taxi_etl_2023, task_id=process_month_02, execution_date=20230104T000000, start_date=20240801T182948, end_date=20240801T183046
[2024-08-01T18:30:46.424+0000] {standard_task_runner.py:109} ERROR - Failed to execute job 29 for task process_month_02 ("['airport_fee'] not in index"; 1497)
[2024-08-01T18:30:46.547+0000] {local_task_job_runner.py:225} INFO - Task exited with return code 1
[2024-08-01T18:30:48.584+0000] {taskinstance.py:2651} INFO - 0 downstream tasks scheduled from follow-on schedule check
