[2024-08-01T17:47:37.421+0000] {logging_mixin.py:149} WARNING - /home/***/.local/lib/python3.7/site-packages/***/utils/sqlalchemy.py:124 DeprecationWarning: The sql_alchemy_conn option in [core] has been moved to the sql_alchemy_conn option in [database] - the old setting has been used, but please update your config.
[2024-08-01T17:47:37.486+0000] {taskinstance.py:1103} INFO - Dependencies all met for dep_context=non-requeueable deps ti=<TaskInstance: nyc_taxi_etl_2023.process_month_01 scheduled__2023-01-06T00:00:00+00:00 [queued]>
[2024-08-01T17:47:37.503+0000] {taskinstance.py:1103} INFO - Dependencies all met for dep_context=requeueable deps ti=<TaskInstance: nyc_taxi_etl_2023.process_month_01 scheduled__2023-01-06T00:00:00+00:00 [queued]>
[2024-08-01T17:47:37.509+0000] {taskinstance.py:1308} INFO - Starting attempt 1 of 2
[2024-08-01T17:47:37.531+0000] {taskinstance.py:1327} INFO - Executing <Task(PythonOperator): process_month_01> on 2023-01-06 00:00:00+00:00
[2024-08-01T17:47:37.539+0000] {standard_task_runner.py:57} INFO - Started process 292 to run task
[2024-08-01T17:47:37.548+0000] {standard_task_runner.py:84} INFO - Running: ['***', 'tasks', 'run', 'nyc_taxi_etl_2023', 'process_month_01', 'scheduled__2023-01-06T00:00:00+00:00', '--job-id', '7', '--raw', '--subdir', 'DAGS_FOLDER/nyc_taxi_etl.py', '--cfg-path', '/tmp/tmpe8rx1gp_']
[2024-08-01T17:47:37.551+0000] {standard_task_runner.py:85} INFO - Job 7: Subtask process_month_01
[2024-08-01T17:47:37.618+0000] {logging_mixin.py:149} WARNING - /home/***/.local/lib/python3.7/site-packages/***/settings.py:195 DeprecationWarning: The sql_alchemy_conn option in [core] has been moved to the sql_alchemy_conn option in [database] - the old setting has been used, but please update your config.
[2024-08-01T17:47:37.684+0000] {task_command.py:410} INFO - Running <TaskInstance: nyc_taxi_etl_2023.process_month_01 scheduled__2023-01-06T00:00:00+00:00 [running]> on host 3a96f4659d34
[2024-08-01T17:47:37.703+0000] {logging_mixin.py:149} WARNING - /home/***/.local/lib/python3.7/site-packages/***/utils/sqlalchemy.py:124 DeprecationWarning: The sql_alchemy_conn option in [core] has been moved to the sql_alchemy_conn option in [database] - the old setting has been used, but please update your config.
[2024-08-01T17:47:38.255+0000] {taskinstance.py:1547} INFO - Exporting env vars: AIRFLOW_CTX_DAG_OWNER='***' AIRFLOW_CTX_DAG_ID='nyc_taxi_etl_2023' AIRFLOW_CTX_TASK_ID='process_month_01' AIRFLOW_CTX_EXECUTION_DATE='2023-01-06T00:00:00+00:00' AIRFLOW_CTX_TRY_NUMBER='1' AIRFLOW_CTX_DAG_RUN_ID='scheduled__2023-01-06T00:00:00+00:00'
[2024-08-01T17:47:53.007+0000] {taskinstance.py:1824} ERROR - Task failed with exception
Traceback (most recent call last):
  File "/home/airflow/.local/lib/python3.7/site-packages/airflow/operators/python.py", line 181, in execute
    return_value = self.execute_callable()
  File "/home/airflow/.local/lib/python3.7/site-packages/airflow/operators/python.py", line 198, in execute_callable
    return self.python_callable(*self.op_args, **self.op_kwargs)
  File "/opt/airflow/dags/nyc_taxi_etl.py", line 27, in process_month
    upload_to_gcs(get_credentials(), os.environ.get('GCP_BUCKET_ID'), f"data/{file_name}", f"raw/{file_name}")
  File "/opt/airflow/scripts/ingest_data.py", line 28, in upload_to_gcs
    blob.upload_from_filename(source_file_name)
  File "/home/airflow/.local/lib/python3.7/site-packages/google/cloud/storage/blob.py", line 2697, in upload_from_filename
    retry=retry,
  File "/home/airflow/.local/lib/python3.7/site-packages/google/cloud/storage/blob.py", line 2553, in upload_from_file
    retry=retry,
  File "/home/airflow/.local/lib/python3.7/site-packages/google/cloud/storage/blob.py", line 2384, in _do_upload
    retry=retry,
  File "/home/airflow/.local/lib/python3.7/site-packages/google/cloud/storage/blob.py", line 2211, in _do_resumable_upload
    retry=retry,
  File "/home/airflow/.local/lib/python3.7/site-packages/google/cloud/storage/blob.py", line 2086, in _initiate_resumable_upload
    timeout=timeout,
  File "/home/airflow/.local/lib/python3.7/site-packages/google/resumable_media/requests/upload.py", line 421, in initiate
    retriable_request, self._get_status_code, self._retry_strategy
  File "/home/airflow/.local/lib/python3.7/site-packages/google/resumable_media/requests/_request_helpers.py", line 155, in wait_and_retry
    response = func()
  File "/home/airflow/.local/lib/python3.7/site-packages/google/resumable_media/requests/upload.py", line 413, in retriable_request
    method, url, data=payload, headers=headers, timeout=timeout
  File "/home/airflow/.local/lib/python3.7/site-packages/google/auth/transport/requests.py", line 545, in request
    self.credentials.before_request(auth_request, method, url, request_headers)
  File "/home/airflow/.local/lib/python3.7/site-packages/google/auth/credentials.py", line 135, in before_request
    self.refresh(request)
  File "/home/airflow/.local/lib/python3.7/site-packages/google/oauth2/service_account.py", line 426, in refresh
    request, self._token_uri, assertion
  File "/home/airflow/.local/lib/python3.7/site-packages/google/oauth2/_client.py", line 304, in jwt_grant
    request, token_uri, body, can_retry=can_retry
  File "/home/airflow/.local/lib/python3.7/site-packages/google/oauth2/_client.py", line 274, in _token_endpoint_request
    _handle_error_response(response_data, retryable_error)
  File "/home/airflow/.local/lib/python3.7/site-packages/google/oauth2/_client.py", line 74, in _handle_error_response
    error_details, response_data, retryable=retryable_error
google.auth.exceptions.RefreshError: ('invalid_grant: Invalid JWT Signature.', {'error': 'invalid_grant', 'error_description': 'Invalid JWT Signature.'})
[2024-08-01T17:47:53.033+0000] {taskinstance.py:1350} INFO - Marking task as UP_FOR_RETRY. dag_id=nyc_taxi_etl_2023, task_id=process_month_01, execution_date=20230106T000000, start_date=20240801T174737, end_date=20240801T174753
[2024-08-01T17:47:53.065+0000] {standard_task_runner.py:109} ERROR - Failed to execute job 7 for task process_month_01 (('invalid_grant: Invalid JWT Signature.', {'error': 'invalid_grant', 'error_description': 'Invalid JWT Signature.'}); 292)
[2024-08-01T17:47:53.139+0000] {local_task_job_runner.py:225} INFO - Task exited with return code 1
[2024-08-01T17:47:53.367+0000] {taskinstance.py:2651} INFO - 0 downstream tasks scheduled from follow-on schedule check
[2024-08-01T18:19:12.767+0000] {logging_mixin.py:149} WARNING - /home/***/.local/lib/python3.7/site-packages/***/utils/sqlalchemy.py:124 DeprecationWarning: The sql_alchemy_conn option in [core] has been moved to the sql_alchemy_conn option in [database] - the old setting has been used, but please update your config.
[2024-08-01T18:19:12.779+0000] {taskinstance.py:1103} INFO - Dependencies all met for dep_context=non-requeueable deps ti=<TaskInstance: nyc_taxi_etl_2023.process_month_01 scheduled__2023-01-06T00:00:00+00:00 [queued]>
[2024-08-01T18:19:12.791+0000] {taskinstance.py:1103} INFO - Dependencies all met for dep_context=requeueable deps ti=<TaskInstance: nyc_taxi_etl_2023.process_month_01 scheduled__2023-01-06T00:00:00+00:00 [queued]>
[2024-08-01T18:19:12.791+0000] {taskinstance.py:1308} INFO - Starting attempt 1 of 2
[2024-08-01T18:19:12.805+0000] {taskinstance.py:1327} INFO - Executing <Task(PythonOperator): process_month_01> on 2023-01-06 00:00:00+00:00
[2024-08-01T18:19:12.815+0000] {standard_task_runner.py:57} INFO - Started process 1060 to run task
[2024-08-01T18:19:12.820+0000] {standard_task_runner.py:84} INFO - Running: ['***', 'tasks', 'run', 'nyc_taxi_etl_2023', 'process_month_01', 'scheduled__2023-01-06T00:00:00+00:00', '--job-id', '24', '--raw', '--subdir', 'DAGS_FOLDER/nyc_taxi_etl.py', '--cfg-path', '/tmp/tmp3j4xm6lz']
[2024-08-01T18:19:12.822+0000] {standard_task_runner.py:85} INFO - Job 24: Subtask process_month_01
[2024-08-01T18:19:12.840+0000] {logging_mixin.py:149} WARNING - /home/***/.local/lib/python3.7/site-packages/***/settings.py:195 DeprecationWarning: The sql_alchemy_conn option in [core] has been moved to the sql_alchemy_conn option in [database] - the old setting has been used, but please update your config.
[2024-08-01T18:19:12.894+0000] {task_command.py:410} INFO - Running <TaskInstance: nyc_taxi_etl_2023.process_month_01 scheduled__2023-01-06T00:00:00+00:00 [running]> on host 6d66194ad4f7
[2024-08-01T18:19:12.910+0000] {logging_mixin.py:149} WARNING - /home/***/.local/lib/python3.7/site-packages/***/utils/sqlalchemy.py:124 DeprecationWarning: The sql_alchemy_conn option in [core] has been moved to the sql_alchemy_conn option in [database] - the old setting has been used, but please update your config.
[2024-08-01T18:19:13.280+0000] {taskinstance.py:1547} INFO - Exporting env vars: AIRFLOW_CTX_DAG_OWNER='***' AIRFLOW_CTX_DAG_ID='nyc_taxi_etl_2023' AIRFLOW_CTX_TASK_ID='process_month_01' AIRFLOW_CTX_EXECUTION_DATE='2023-01-06T00:00:00+00:00' AIRFLOW_CTX_TRY_NUMBER='1' AIRFLOW_CTX_DAG_RUN_ID='scheduled__2023-01-06T00:00:00+00:00'
[2024-08-01T18:20:06.307+0000] {transform_data.py:18} INFO - Processing data for 2023-01
[2024-08-01T18:20:06.319+0000] {transform_data.py:19} INFO - Columns in the dataset: ['VendorID', 'tpep_pickup_datetime', 'tpep_dropoff_datetime', 'passenger_count', 'trip_distance', 'RatecodeID', 'store_and_fwd_flag', 'PULocationID', 'DOLocationID', 'payment_type', 'fare_amount', 'extra', 'mta_tax', 'tip_amount', 'tolls_amount', 'improvement_surcharge', 'total_amount', 'congestion_surcharge', 'airport_fee']
[2024-08-01T18:20:22.574+0000] {transform_data.py:130} INFO - Created fact_trip table for 2023-01
[2024-08-01T18:20:27.868+0000] {logging_mixin.py:149} INFO - Loaded dim_vendor for 2023-01 to BigQuery
[2024-08-01T18:20:36.266+0000] {logging_mixin.py:149} INFO - Loaded dim_rate_code for 2023-01 to BigQuery
[2024-08-01T18:20:40.772+0000] {logging_mixin.py:149} INFO - Loaded dim_payment_type for 2023-01 to BigQuery
[2024-08-01T18:20:45.065+0000] {logging_mixin.py:149} INFO - Loaded dim_location for 2023-01 to BigQuery
[2024-08-01T18:22:35.067+0000] {logging_mixin.py:149} INFO - Loaded fact_trip for 2023-01 to BigQuery
[2024-08-01T18:22:35.083+0000] {python.py:183} INFO - Done. Returned value was: None
[2024-08-01T18:22:35.168+0000] {taskinstance.py:1350} INFO - Marking task as SUCCESS. dag_id=nyc_taxi_etl_2023, task_id=process_month_01, execution_date=20230106T000000, start_date=20240801T181912, end_date=20240801T182235
[2024-08-01T18:22:35.330+0000] {local_task_job_runner.py:225} INFO - Task exited with return code 0
[2024-08-01T18:22:35.912+0000] {taskinstance.py:2651} INFO - 1 downstream tasks scheduled from follow-on schedule check
