[2024-08-01T18:22:40.607+0000] {logging_mixin.py:149} WARNING - /home/***/.local/lib/python3.7/site-packages/***/utils/sqlalchemy.py:124 DeprecationWarning: The sql_alchemy_conn option in [core] has been moved to the sql_alchemy_conn option in [database] - the old setting has been used, but please update your config.
[2024-08-01T18:22:40.629+0000] {taskinstance.py:1103} INFO - Dependencies all met for dep_context=non-requeueable deps ti=<TaskInstance: nyc_taxi_etl_2023.process_month_02 scheduled__2023-01-02T00:00:00+00:00 [queued]>
[2024-08-01T18:22:40.640+0000] {taskinstance.py:1103} INFO - Dependencies all met for dep_context=requeueable deps ti=<TaskInstance: nyc_taxi_etl_2023.process_month_02 scheduled__2023-01-02T00:00:00+00:00 [queued]>
[2024-08-01T18:22:40.640+0000] {taskinstance.py:1308} INFO - Starting attempt 2 of 2
[2024-08-01T18:22:40.654+0000] {taskinstance.py:1327} INFO - Executing <Task(PythonOperator): process_month_02> on 2023-01-02 00:00:00+00:00
[2024-08-01T18:22:40.664+0000] {standard_task_runner.py:57} INFO - Started process 1183 to run task
[2024-08-01T18:22:40.670+0000] {standard_task_runner.py:84} INFO - Running: ['***', 'tasks', 'run', 'nyc_taxi_etl_2023', 'process_month_02', 'scheduled__2023-01-02T00:00:00+00:00', '--job-id', '25', '--raw', '--subdir', 'DAGS_FOLDER/nyc_taxi_etl.py', '--cfg-path', '/tmp/tmpsr11f5eo']
[2024-08-01T18:22:40.672+0000] {standard_task_runner.py:85} INFO - Job 25: Subtask process_month_02
[2024-08-01T18:22:40.690+0000] {logging_mixin.py:149} WARNING - /home/***/.local/lib/python3.7/site-packages/***/settings.py:195 DeprecationWarning: The sql_alchemy_conn option in [core] has been moved to the sql_alchemy_conn option in [database] - the old setting has been used, but please update your config.
[2024-08-01T18:22:40.733+0000] {task_command.py:410} INFO - Running <TaskInstance: nyc_taxi_etl_2023.process_month_02 scheduled__2023-01-02T00:00:00+00:00 [running]> on host 6d66194ad4f7
[2024-08-01T18:22:40.747+0000] {logging_mixin.py:149} WARNING - /home/***/.local/lib/python3.7/site-packages/***/utils/sqlalchemy.py:124 DeprecationWarning: The sql_alchemy_conn option in [core] has been moved to the sql_alchemy_conn option in [database] - the old setting has been used, but please update your config.
[2024-08-01T18:22:41.118+0000] {taskinstance.py:1547} INFO - Exporting env vars: AIRFLOW_CTX_DAG_OWNER='***' AIRFLOW_CTX_DAG_ID='nyc_taxi_etl_2023' AIRFLOW_CTX_TASK_ID='process_month_02' AIRFLOW_CTX_EXECUTION_DATE='2023-01-02T00:00:00+00:00' AIRFLOW_CTX_TRY_NUMBER='2' AIRFLOW_CTX_DAG_RUN_ID='scheduled__2023-01-02T00:00:00+00:00'
[2024-08-01T18:23:32.681+0000] {transform_data.py:18} INFO - Processing data for 2023-02
[2024-08-01T18:23:32.696+0000] {transform_data.py:19} INFO - Columns in the dataset: ['VendorID', 'tpep_pickup_datetime', 'tpep_dropoff_datetime', 'passenger_count', 'trip_distance', 'RatecodeID', 'store_and_fwd_flag', 'PULocationID', 'DOLocationID', 'payment_type', 'fare_amount', 'extra', 'mta_tax', 'tip_amount', 'tolls_amount', 'improvement_surcharge', 'total_amount', 'congestion_surcharge', 'Airport_fee']
[2024-08-01T18:23:37.576+0000] {transform_data.py:77} ERROR - Error processing data for 2023-02: "['airport_fee'] not in index"
[2024-08-01T18:23:37.594+0000] {taskinstance.py:1824} ERROR - Task failed with exception
Traceback (most recent call last):
  File "/home/airflow/.local/lib/python3.7/site-packages/airflow/operators/python.py", line 181, in execute
    return_value = self.execute_callable()
  File "/home/airflow/.local/lib/python3.7/site-packages/airflow/operators/python.py", line 198, in execute_callable
    return self.python_callable(*self.op_args, **self.op_kwargs)
  File "/opt/airflow/dags/nyc_taxi_etl.py", line 28, in process_month
    clean_and_transform_data(year, month)
  File "/opt/airflow/scripts/transform_data.py", line 74, in clean_and_transform_data
    create_fact_table(df, year, month, rate_code_column)
  File "/opt/airflow/scripts/transform_data.py", line 123, in create_fact_table
    fact_trip = df[fact_trip_columns]
  File "/home/airflow/.local/lib/python3.7/site-packages/pandas/core/frame.py", line 3464, in __getitem__
    indexer = self.loc._get_listlike_indexer(key, axis=1)[1]
  File "/home/airflow/.local/lib/python3.7/site-packages/pandas/core/indexing.py", line 1314, in _get_listlike_indexer
    self._validate_read_indexer(keyarr, indexer, axis)
  File "/home/airflow/.local/lib/python3.7/site-packages/pandas/core/indexing.py", line 1377, in _validate_read_indexer
    raise KeyError(f"{not_found} not in index")
KeyError: "['airport_fee'] not in index"
[2024-08-01T18:23:37.649+0000] {taskinstance.py:1350} INFO - Marking task as FAILED. dag_id=nyc_taxi_etl_2023, task_id=process_month_02, execution_date=20230102T000000, start_date=20240801T182240, end_date=20240801T182337
[2024-08-01T18:23:37.683+0000] {standard_task_runner.py:109} ERROR - Failed to execute job 25 for task process_month_02 ("['airport_fee'] not in index"; 1183)
[2024-08-01T18:23:37.800+0000] {local_task_job_runner.py:225} INFO - Task exited with return code 1
[2024-08-01T18:23:38.291+0000] {taskinstance.py:2651} INFO - 0 downstream tasks scheduled from follow-on schedule check
